Workbook

Sheet Propuesta actualizada
A1: Fase | B1: Subfase | C1: Tarea Concreta | D1: COMERCIAL | F1: DIRECCION | H1: UN-SWLABG | P1: UN-UX | V1: TOTAL
H2: BACK | J2: FRONT | L2: SOPORTE | N2: MK | P2: UX | R2: UI | T2: WP-MAQ
D3: =SUM(D5:D85) -> 0 | E3: =SUM(E5:E85) -> 0 | F3: =SUM(F5:F85) -> 0 | G3: =SUM(G5:G85) -> 0 | H3: =SUM(H5:H85) -> 0 | I3: =SUM(I5:I85) -> 0 | J3: =SUM(J5:J85) -> 0 | K3: =SUM(K5:K85) -> 0 | ... W3: =SUM(W5:W85) -> 0
D4: MIN | E4: MAX | F4: MIN | G4: MAX | H4: MIN | I4: MAX | J4: MIN | K4: MAX | L4: MIN | M4: MAX | N4: MIN | O4: MAX | P4: MIN | Q4: MAX | R4: MIN | S4: MAX | T4: MIN | U4: MAX | V4: MIN | W4: MAX
A5: Análisis | B5: Analisis | C5: Preventa | D5: 0 | E5: 0 | V5: =SUM(D5,F5,H5,J5,L5,N5,P5,R5,T5) -> 0 | W5: =SUM(E5,G5,I5,K5,M5,O5,Q5,S5,U5) -> 0
C6: Análisis software | F6: 0 | G6: 0 | H6: 0 | I6: 0 | J6: 0 | K6: 0 | T6: 0 | U6: 0 | V6: =SUM(D6,F6,H6,J6,L6,N6,P6,R6,T6) -> 0 | W6: =SUM(E6,G6,I6,K6,M6,O6,Q6,S6,U6) -> 0
C7: Kickoff | P7: 0 | Q7: 0 | V7: =SUM(D7,F7,H7,J7,L7,N7,P7,R7,T7) -> 0 | W7: =SUM(E7,G7,I7,K7,M7,O7,Q7,S7,U7) -> 0
C8: Analisis contexto inicial | P8: 0 | Q8: 0 | R8: 0 | S8: 0 | T8: 0 | U8: 0 | V8: =SUM(D8,F8,H8,J8,L8,N8,P8,R8,T8) -> 0 | W8: =SUM(E8,G8,I8,K8,M8,O8,Q8,S8,U8) -> 0
C9: 5W | P9: 0 | Q9: 0 | V9: =SUM(D9,F9,H9,J9,L9,N9,P9,R9,T9) -> 0 | W9: =SUM(E9,G9,I9,K9,M9,O9,Q9,S9,U9) -> 0
C10: Auditoría y análisis de estado SEO | N10: 0 | O10: 0 | V10: =SUM(D10,F10,H10,J10,L10,N10,P10,R10,T10) -> 0 | W10: =SUM(E10,G10,I10,K10,M10,O10,Q10,S10,U10) -> 0
C11: Estudio de palabras clave | N11: 0 | O11: 0 | V11: =SUM(D11,F11,H11,J11,L11,N11,P11,R11,T11) -> 0 | W11: =SUM(E11,G11,I11,K11,M11,O11,Q11,S11,U11) -> 0
B12: Investigacion | H12: 0 | I12: 0 | J12: 0 | K12: 0 | T12: 0 | U12: 0 | V12: =SUM(D12,F12,H12,J12,L12,N12,P12,R12,T12) -> 0 | W12: =SUM(E12,G12,I12,K12,M12,O12,Q12,S12,U12) -> 0
B13: Infraestructura | H13: 0 | I13: 0 | J13: 0 | K13: 0 | T13: 0 | U13: 0 | V13: =SUM(D13,F13,H13,J13,L13,N13,P13,R13,T13) -> 0 | W13: =SUM(E13,G13,I13,K13,M13,O13,Q13,S13,U13) -> 0
A14: Desarrollo | B14: Discovery | C14: Benchamark | N14: 0 | O14: 0 | P14: 0 | Q14: 0 | V14: =SUM(D14,F14,H14,J14,L14,N14,P14,R14,T14) -> 0 | W14: =SUM(E14,G14,I14,K14,M14,O14,Q14,S14,U14) -> 0
C15: Desk Research | P15: 0 | Q15: 0 | V15: =SUM(D15,F15,H15,J15,L15,N15,P15,R15,T15) -> 0 | W15: =SUM(E15,G15,I15,K15,M15,O15,Q15,S15,U15) -> 0
C16: Entrevistas | P16: 0 | Q16: 0 | V16: =SUM(D16,F16,H16,J16,L16,N16,P16,R16,T16) -> 0 | W16: =SUM(E16,G16,I16,K16,M16,O16,Q16,S16,U16) -> 0
C17: Cuestionarios | P17: 0 | Q17: 0 | V17: =SUM(D17,F17,H17,J17,L17,N17,P17,R17,T17) -> 0 | W17: =SUM(E17,G17,I17,K17,M17,O17,Q17,S17,U17) -> 0
C18: Analisis de métricas | P18: 0 | Q18: 0 | V18: =SUM(D18,F18,H18,J18,L18,N18,P18,R18,T18) -> 0 | W18: =SUM(E18,G18,I18,K18,M18,O18,Q18,S18,U18) -> 0
C19: Focus Group | P19: 0 | Q19: 0 | V19: =SUM(D19,F19,H19,J19,L19,N19,P19,R19,T19) -> 0 | W19: =SUM(E19,G19,I19,K19,M19,O19,Q19,S19,U19) -> 0
C20: Recorrido cognitivo | P20: 0 | Q20: 0 | V20: =SUM(D20,F20,H20,J20,L20,N20,P20,R20,T20) -> 0 | W20: =SUM(E20,G20,I20,K20,M20,O20,Q20,S20,U20) -> 0
C21: Evaluación heurística | P21: 0 | Q21: 0 | V21: =SUM(D21,F21,H21,J21,L21,N21,P21,R21,T21) -> 0 | W21: =SUM(E21,G21,I21,K21,M21,O21,Q21,S21,U21) -> 0
C22: Observación | P22: 0 | Q22: 0 | V22: =SUM(D22,F22,H22,J22,L22,N22,P22,R22,T22) -> 0 | W22: =SUM(E22,G22,I22,K22,M22,O22,Q22,S22,U22) -> 0
C23: Card sorting | P23: 0 | Q23: 0 | V23: =SUM(D23,F23,H23,J23,L23,N23,P23,R23,T23) -> 0 | W23: =SUM(E23,G23,I23,K23,M23,O23,Q23,S23,U23) -> 0
C24: Registro y analisis de métricas | P24: 0 | Q24: 0 | V24: =SUM(D24,F24,H24,J24,L24,N24,P24,R24,T24) -> 0 | W24: =SUM(E24,G24,I24,K24,M24,O24,Q24,S24,U24) -> 0
C25: Tree testing | P25: 0 | Q25: 0 | V25: =SUM(D25,F25,H25,J25,L25,N25,P25,R25,T25) -> 0 | W25: =SUM(E25,G25,I25,K25,M25,O25,Q25,S25,U25) -> 0
B26: Evaluacion | C26: QA | R26: 0 | S26: 0 | V26: =SUM(D26,F26,H26,J26,L26,N26,P26,R26,T26) -> 0 | W26: =SUM(E26,G26,I26,K26,M26,O26,Q26,S26,U26) -> 0
C27: Test con usuarios | P27: 0 | Q27: 0 | V27: =SUM(D27,F27,H27,J27,L27,N27,P27,R27,T27) -> 0 | W27: =SUM(E27,G27,I27,K27,M27,O27,Q27,S27,U27) -> 0
B28: Sintesis | C28: Conclusiones discovery | P28: 0 | Q28: 0 | V28: =SUM(D28,F28,H28,J28,L28,N28,P28,R28,T28) -> 0 | W28: =SUM(E28,G28,I28,K28,M28,O28,Q28,S28,U28) -> 0
C29: Hallazgos e insights | P29: 0 | Q29: 0 | V29: =SUM(D29,F29,H29,J29,L29,N29,P29,R29,T29) -> 0 | W29: =SUM(E29,G29,I29,K29,M29,O29,Q29,S29,U29) -> 0
C30: User persona | P30: 0 | Q30: 0 | V30: =SUM(D30,F30,H30,J30,L30,N30,P30,R30,T30) -> 0 | W30: =SUM(E30,G30,I30,K30,M30,O30,Q30,S30,U30) -> 0
C31: Persona minimalista | P31: 0 | Q31: 0 | V31: =SUM(D31,F31,H31,J31,L31,N31,P31,R31,T31) -> 0 | W31: =SUM(E31,G31,I31,K31,M31,O31,Q31,S31,U31) -> 0
C32: Escenario / Storyboard | P32: 0 | Q32: 0 | V32: =SUM(D32,F32,H32,J32,L32,N32,P32,R32,T32) -> 0 | W32: =SUM(E32,G32,I32,K32,M32,O32,Q32,S32,U32) -> 0
C33: Happy / Unhappy path | P33: 0 | Q33: 0 | V33: =SUM(D33,F33,H33,J33,L33,N33,P33,R33,T33) -> 0 | W33: =SUM(E33,G33,I33,K33,M33,O33,Q33,S33,U33) -> 0
C34: Lean UX | P34: 0 | Q34: 0 | V34: =SUM(D34,F34,H34,J34,L34,N34,P34,R34,T34) -> 0 | W34: =SUM(E34,G34,I34,K34,M34,O34,Q34,S34,U34) -> 0
C35: Problem statement | P35: 0 | Q35: 0 | V35: =SUM(D35,F35,H35,J35,L35,N35,P35,R35,T35) -> 0 | W35: =SUM(E35,G35,I35,K35,M35,O35,Q35,S35,U35) -> 0
C36: User journey | P36: 0 | Q36: 0 | V36: =SUM(D36,F36,H36,J36,L36,N36,P36,R36,T36) -> 0 | W36: =SUM(E36,G36,I36,K36,M36,O36,Q36,S36,U36) -> 0
C37: Matriz de complejidad | P37: 0 | Q37: 0 | V37: =SUM(D37,F37,H37,J37,L37,N37,P37,R37,T37) -> 0 | W37: =SUM(E37,G37,I37,K37,M37,O37,Q37,S37,U37) -> 0
C38: Mapa de empatía | P38: 0 | Q38: 0 | V38: =SUM(D38,F38,H38,J38,L38,N38,P38,R38,T38) -> 0 | W38: =SUM(E38,G38,I38,K38,M38,O38,Q38,S38,U38) -> 0
C39: Requisitos y funcionalidades | P39: 0 | Q39: 0 | V39: =SUM(D39,F39,H39,J39,L39,N39,P39,R39,T39) -> 0 | W39: =SUM(E39,G39,I39,K39,M39,O39,Q39,S39,U39) -> 0
B40: Frontend | C40: Funcionalidad 1 | J40: 0 | K40: 0 | T40: 0 | U40: 0 | V40: =SUM(D40,F40,H40,J40,L40,N40,P40,R40,T40) -> 0 | W40: =SUM(E40,G40,I40,K40,M40,O40,Q40,S40,U40) -> 0
...

Sheet UX
A1: Benchmark | B1: 0
A2: Entrevistas | B2: 0
A3: Recorrido cognitivo | B3: 0
A4: Observación | B4: 0
A5: Test usuarios | B5: 0
A6: Tree testing | B6: 0
A7: Card sorting | B7: 0
A8: User persona | B8: 0
A9: Personas minimalista | B9: 0
A10: Escenarios/Storyboards | B10: 0
A11: Happy/Unhappy path | B11: 0
A12: User journey | B12: 0
A13: Diagramas de flujo | B13: 0
A15: Metodología | B15: Mín. | C15: Máx. | D15: Mín. redondeo | E15: Máx. redondeo
A16: Benchmark | B16: =($B1*Metodologias!B5) -> 0 | C16: =($B1*Metodologias!C5) -> 0 | D16: =ROUND(B16/2, 0)*2 -> 0 | E16: =ROUND(C16/2, 0)*2 -> 0
A17: Desk Research | B17: =(Metodologias!B6) -> 8 | C17: =(Metodologias!C6) -> 12 | D17: =ROUND(B17/2, 0)*2 -> 8 | E17: =ROUND(C17/2, 0)*2 -> 12
A18: Entrevistas | B18: =($B2*Metodologias!B7) -> 0 | C18: =($B2*Metodologias!C7) -> 0 | D18: =ROUND(B18/2, 0)*2 -> 0 | E18: =ROUND(C18/2, 0)*2 -> 0
A19: Encuestas | B19: =(Metodologias!B8) -> 12 | C19: =(Metodologias!C8) -> 16 | D19: =ROUND(B19/2, 0)*2 -> 12 | E19: =ROUND(C19/2, 0)*2 -> 16
A20: Focus Group | B20: =(Metodologias!B9) -> 8 | C20: =(Metodologias!C9) -> 12 | D20: =ROUND(B20/2, 0)*2 -> 8 | E20: =ROUND(C20/2, 0)*2 -> 12
A21: Report de investigación | B21: =(Metodologias!B10) -> 6 | C21: =(Metodologias!C10) -> 8 | D21: =ROUND(B21/2, 0)*2 -> 6 | E21: =ROUND(C21/2, 0)*2 -> 8
A22: Recorrido cognitivo | B22: =($B3*Metodologias!B11) -> 0 | C22: =($B3*Metodologias!C11) -> 0 | D22: =ROUND(B22/2, 0)*2 -> 0 | E22: =ROUND(C22/2, 0)*2 -> 0
A23: Evaluación heurística | B23: =(Metodologias!B12) -> 16 | C23: =(Metodologias!C12) -> 20 | D23: =ROUND(B23/2, 0)*2 -> 16 | E23: =ROUND(C23/2, 0)*2 -> 20
A24: Análisis de métricas | B24: =(Metodologias!B13) -> 12 | C24: =(Metodologias!C13) -> 18 | D24: =ROUND(B24/2, 0)*2 -> 12 | E24: =ROUND(C24/2, 0)*2 -> 18
A25: Observación | B25: =($B4*Metodologias!B14) -> 0 | C25: =($B4*Metodologias!C14) -> 0 | D25: =ROUND(B25/2, 0)*2 -> 0 | E25: =ROUND(C25/2, 0)*2 -> 0
A26: Test con usuarios | B26: =($B5*Metodologias!B15) -> 0 | C26: =($B5*Metodologias!C15) -> 0 | D26: =ROUND(B26/2, 0)*2 -> 0 | E26: =ROUND(C26/2, 0)*2 -> 0
A27: Tree testing | B27: =($B6*Metodologias!B16) -> 0 | C27: =($B6*Metodologias!C16) -> 0 | D27: =ROUND(B27/2, 0)*2 -> 0 | E27: =ROUND(C27/2, 0)*2 -> 0
A28: Card sorting | B28: =($B7*Metodologias!B17) -> 0 | C28: =($B7*Metodologias!C17) -> 0 | D28: =ROUND(B28/2, 0)*2 -> 0 | E28: =ROUND(C28/2, 0)*2 -> 0
A29: Insights | B29: =(Metodologias!B18) -> 6 | C29: =(Metodologias!C18) -> 8 | D29: =ROUND(B29/2, 0)*2 -> 6 | E29: =ROUND(C29/2, 0)*2 -> 8
A30: User persona | B30: =($B8*Metodologias!B19) -> 0 | C30: =($B8*Metodologias!C19) -> 0 | D30: =ROUND(B30/2, 0)*2 -> 0 | E30: =ROUND(C30/2, 0)*2 -> 0
A31: Persona minimalista | B31: =($B9*Metodologias!B20) -> 0 | C31: =($B9*Metodologias!C20) -> 0 | D31: =ROUND(B31/2, 0)*2 -> 0 | E31: =ROUND(C31/2, 0)*2 -> 0
A32: Escenarios / Storyboards | B32: =($B10*Metodologias!B21) -> 0 | C32: =($B10*Metodologias!C21) -> 0 | D32: =ROUND(B32/2, 0)*2 -> 0 | E32: =ROUND(C32/2, 0)*2 -> 0
A33: Happy / Unhappy path | B33: =($B11*Metodologias!B22) -> 0 | C33: =($B11*Metodologias!C22) -> 0 | D33: =ROUND(B33/2, 0)*2 -> 0 | E33: =ROUND(C33/2, 0)*2 -> 0
A34: User Journey | B34: =($B12*Metodologias!B23) -> 0 | C34: =($B12*Metodologias!C23) -> 0 | D34: =ROUND(B34/2, 0)*2 -> 0 | E34: =ROUND(C34/2, 0)*2 -> 0
A35: Lean UX | B35: =(Metodologias!B24) -> 8 | C35: =(Metodologias!C24) -> 12 | D35: =ROUND(B35/2, 0)*2 -> 8 | E35: =ROUND(C35/2, 0)*2 -> 12
A36: Problem statement | B36: =(Metodologias!B25) -> 2 | C36: =(Metodologias!C25) -> 4 | D36: =ROUND(B36/2, 0)*2 -> 2 | E36: =ROUND(C36/2, 0)*2 -> 4
A37: Matriz de complejidad | B37: =(Metodologias!B26) -> 2 | C37: =(Metodologias!C26) -> 4 | D37: =ROUND(B37/2, 0)*2 -> 2 | E37: =ROUND(C37/2, 0)*2 -> 4
A38: Mapa empatia | B38: =(Metodologias!B27) -> 4 | C38: =(Metodologias!C27) -> 6 | D38: =ROUND(B38/2, 0)*2 -> 4 | E38: =ROUND(C38/2, 0)*2 -> 6
A39: Requisitos y funcionalidades | B39: =(Metodologias!B28) -> 4 | C39: =(Metodologias!C28) -> 12 | D39: =ROUND(B39/2, 0)*2 -> 4 | E39: =ROUND(C39/2, 0)*2 -> 12
A40: Arquitectura | B40: =(Metodologias!B29) -> 16 | C40: =(Metodologias!C29) -> 24 | D40: =ROUND(B40/2, 0)*2 -> 16 | E40: =ROUND(C40/2, 0)*2 -> 24
A41: Diagramas de flujo | B41: =($B13*Metodologias!B30) -> 0 | C41: =($B13*Metodologias!C30) -> 0 | D41: =ROUND(B41/2, 0)*2 -> 0 | E41: =ROUND(C41/2, 0)*2 -> 0
...

Sheet Metodologias
A1: Tarea | B1: Min | C1: Max
A2: Kickoff | B2: 2 | C2: 4
A3: Analisis contexto | B3: 4 | C3: 6
A4: 5W | B4: 1 | C4: 2
A5: Benchmark | B5: 4 | C5: 6
A6: Desk Research | B6: 8 | C6: 12
A7: Entrevistas | B7: 4 | C7: 6
A8: Encuestas | B8: 12 | C8: 16
A9: Focus Group | B9: 8 | C9: 12
A10: Report de investigación | B10: 6 | C10: 8
A11: Recorrido cognitivo | B11: 4 | C11: 6
A12: Evaluación heurística | B12: 16 | C12: 20
A13: Análisis de métricas | B13: 12 | C13: 18
... A29: Arquitectura | B29: 16 | C29: 24

Sheet UI
D1: Mín. | E1: Máx. | F1: Multiplicador Controlar
C2: Margen Global Error (%) | D2: 0.05 | E2: 0.05
A3: Controlo del tema (S/N) | B3: S | C3: Tiempo Análisis (h) | D3: 2 | E3: 4 | F3: 2
A4: P1. Pantalla sencilla | B4: =COUNTIF(Desglose!B2:B999,"P1") -> 0 | C4: Wireframes P1 (h) | D4: 1 | E4: 2
A5: P2. Pantalla standard | B5: =COUNTIF(Desglose!B2:B1000,"P2") -> 0 | C5: Wireframes P2 (h) | D5: 2 | E5: 3
A6: P3. Pantalla compleja | B6: =COUNTIF(Desglose!B2:B1001,"P3") -> 0 | C6: Wireframe P3 (h) | D6: 4 | E6: 6
A7: P4. Pantalla compleja+ | B7: =COUNTIF(Desglose!B2:B1002,"P4") -> 0 | C7: Wireframe P4 (h) | D7: 6 | E7: 8
A8: Adaptar 1 resolución (S/N) | B8: S | C8: HF P1 (h) | D8: 0.5 | E8: 1
A9: Adaptar 2 resoluciones (S/N) | B9: N | C9: HF P2 (h) | D9: 1 | E9: 1.5
C10: HF P3 (h) | D10: 1.5 | E10: 2
C11: HF P4 (h) | D11: 2 | E11: 4
C12: Adaptacion 1 resolucion (%) | D12: 0.3 | E12: 0.4
C13: Adaptacion 2 resoluciones (%) | D13: 0.3 | E13: 0.4
C14: Look&feel | D14: 8 | E14: 12
A17: Fase | B17: Subfase | D17: Tiempo mínimo | E17: Tiempo máximo | F17: Tiempo mín. redondeo | G17: Tiempo max. redondeo
A18: Analisis | B18: Analisis | D18: =IF($B$3="S",D3,D3*$F$3) -> 2 | E18: =IF($B$3="S",E3,E3*$F$3) -> 4 | F18: =ROUND(D18/2, 0)*2 -> 2 | G18: =ROUND(E18/2, 0)*2 -> 4
B19: Wireframes | D19: =($B4*D4+$B5*D5+$B6*D6+$B7*D7) -> 0 | E19: =($B4*E4+$B5*E5+$B6*E6+$B7*E7) -> 0 | F19: =ROUND(D19/2, 0)*2 -> 0 | G19: =ROUND(E19/2, 0)*2 -> 0
B20: HF | D20: =SUM(($B4*D8+$B5*D9+$B6*D10+$B7*D11+D14)+(IF($B$8="S",(($B4*D8+$B5*D9+$B6*D10+$B7*D11)*D12),"0"))+(IF($B$9="S",(($B4*D8+$B5*D9+$B6*D10+$B7*D11)*D13),"0"))) -> 8 | E20: =SUM(($B4*E8+$B5*E9+$B6*E10+$B7*E11+E14)+(IF($B$8="S",(($B4*E8+$B5*E9+$B6*E10+$B7*E11)*E12),"0"))+(IF($B$9="S",(($B4*E8+$B5*E9+$B6*E10+$B7*E11)*E13),"0"))) -> 12 | F20: =ROUND((D20+D21)/2, 0)*2 -> 10 | G20: =ROUND((E20+E21)/2, 0)*2 -> 14
B21: Assets | D21: 1 | E21: 2
B22: QA | D22: 2 | E22: 4 | F22: =ROUND(D22/2, 0)*2 -> 2 | G22: =ROUND(E22/2, 0)*2 -> 4

Sheet Desglose
A1: Descripción | B1: Tipo pantalla
A2: Pantalla 1
A3: Pantalla 1
A4: Pantalla 1
A5: Pantalla 1
A6: Pantalla 1
